<?xml version="1.0" encoding="utf-8"?>
<!-- This URDF was automatically created by SolidWorks to URDF Exporter! Originally created by Stephen Brawner (brawner@gmail.com) 
     Commit Version: 1.6.0-4-g7f85cfe  Build Version: 1.6.7995.38578
     For more information, please see http://wiki.ros.org/sw_urdf_exporter -->
<robot
  name="alohamini2pro_urdf">

 <link name="root">
    <inertial>
      <mass value="0"/>
      <inertia ixx="0.00" ixy="0.00" ixz="0.00" iyy="0.00" iyz="0.00" izz="0.00"/>
    </inertial>
  </link>

  <link name="root_x_link">
    <inertial>
      <mass value="0"/>
      <inertia ixx="0.00" ixy="0.00" ixz="0.00" iyy="0.00" iyz="0.00" izz="0.00"/>
    </inertial>
  </link>

  <link name="root_y_link">
    <inertial>
      <mass value="0"/>
      <inertia ixx="0.00" ixy="0.00" ixz="0.00" iyy="0.00" iyz="0.00" izz="0.00"/>
    </inertial>
  </link>

  <!-- Virtual Base Joints -->
  <joint name="root_x_axis_joint" type="prismatic">
    <parent link="root"/>
    <child link="root_x_link"/>
    <axis xyz="1 0 0"/>
    <limit effort="500" lower="-20" upper="20" velocity="1.0"/>
    <dynamics damping="100.0" friction="10"/>
  </joint>

  <joint name="root_y_axis_joint" type="prismatic">
    <parent link="root_x_link"/>
    <child link="root_y_link"/>
    <axis xyz="0 1 0"/>
    <limit effort="500" lower="-20" upper="20" velocity="1.0"/>
    <dynamics damping="100.0" friction="10"/>
  </joint>

  <joint name="root_z_rotation_joint" type="continuous">
    <parent link="root_y_link"/>
    <child link="base_link"/>
    <axis xyz="0 0 1"/>
    <dynamics damping="100.0" friction="10"/>
  </joint>




  <link
    name="base_link">
    <inertial>
      <origin
        xyz="-0.000612633316587952 0.0211982181323527 0.18480862701929"
        rpy="0 0 0" />
      <mass
        value="8.86139507603108" />
      <inertia
        ixx="0.0397444790644058"
        ixy="2.09099577497681E-05"
        ixz="-2.08628911381616E-06"
        iyy="0.037893946360475"
        iyz="-0.000833813445075086"
        izz="0.0455979380299635" />
    </inertial>
    <visual>
      <origin
        xyz="0 0 0"
        rpy="0 0 0" />
      <geometry>
        <mesh
          filename="package://alohamini2pro_urdf/alohamini2pro_meshes/base_link.STL" />
      </geometry>
      <material
        name="">
        <color
          rgba="0.752941176470588 0.752941176470588 0.752941176470588 1" />
      </material>
    </visual>
    <collision>
      <origin
        xyz="0 0 0"
        rpy="0 0 0" />
      <geometry>
        <mesh
          filename="package://alohamini2pro_urdf/alohamini2pro_meshes/base_link.STL" />
      </geometry>
    </collision>
  </link>
  <link
    name="vertical_link">
    <inertial>
      <origin
        xyz="-0.000482088964298404 -0.0410546516336574 0.425062657231215"
        rpy="0 0 0" />
      <mass
        value="1.2335419276614" />
      <inertia
        ixx="0.00155091989851972"
        ixy="1.5485059025087E-05"
        ixz="-8.46685606879424E-07"
        iyy="0.00400826783390671"
        iyz="2.63497049488797E-05"
        izz="0.00325969641023924" />
    </inertial>
    <visual>
      <origin
        xyz="0 0 0"
        rpy="0 0 0" />
      <geometry>
        <mesh
          filename="package://alohamini2pro_urdf/alohamini2pro_meshes/vertical_link.STL" />
      </geometry>
      <material
        name="">
        <color
          rgba="0.752941176470588 0.752941176470588 0.752941176470588 1" />
      </material>
    </visual>
    <collision>
      <origin
        xyz="0 0 0"
        rpy="0 0 0" />
      <geometry>
        <mesh
          filename="package://alohamini2pro_urdf/alohamini2pro_meshes/vertical_link.STL" />
      </geometry>
    </collision>
  </link>
  <joint
    name="vertical_move"
    type="prismatic">
    <origin
      xyz="0 0 0.096196"
      rpy="0 0 0" />
    <parent
      link="base_link" />
    <child
      link="vertical_link" />
    <axis
      xyz="0 0 1" />
    <limit
      lower="-0.3"
      upper="0.3"
      effort="0"
      velocity="0" />
  </joint>
  <link
    name="chest_camera">
    <inertial>
      <origin
        xyz="0.318266847861093 -0.000370150448734445 -0.0826066487973801"
        rpy="0 0 0" />
      <mass
        value="10.0950259540064" />
      <inertia
        ixx="0.137148263631157"
        ixy="0.000755549795832478"
        ixz="-0.00219205951256805"
        iyy="0.491701304000814"
        iyz="0.000197672739569789"
        izz="0.48954229298899" />
    </inertial>
    <visual>
      <origin
        xyz="0 0 0"
        rpy="0 0 0" />
      <geometry>
        <mesh
          filename="package://alohamini2pro_urdf/alohamini2pro_meshes/chest_camera.STL" />
      </geometry>
      <material
        name="">
        <color
          rgba="0.752941176470588 0.752941176470588 0.752941176470588 1" />
      </material>
    </visual>
    <collision>
      <origin
        xyz="0 0 0"
        rpy="0 0 0" />
      <geometry>
        <mesh
          filename="package://alohamini2pro_urdf/alohamini2pro_meshes/chest_camera.STL" />
      </geometry>
    </collision>
  </link>
  <joint
    name="chest_camera_joint7_dp"
    type="fixed">
    <origin
      xyz="-0.000225761875701821 -0.0690163597583236 0.447985436693376"
      rpy="1.57079632679491 1.5707963267949 0" />
    <parent
      link="vertical_link" />
    <child
      link="chest_camera" />
    <axis
      xyz="0 0 0" />
  </joint>
  <link
    name="Link2_dp">
    <inertial>
      <origin
        xyz="-0.162572857658571 -0.0120532949042898 -0.146727084322472"
        rpy="0 0 0" />
      <mass
        value="10.0950259540064" />
      <inertia
        ixx="0.137148343426468"
        ixy="-0.002276080109348"
        ixz="0.000472620111779352"
        iyy="0.489910856141119"
        iyz="0.000836241495811028"
        izz="0.491332661053374" />
    </inertial>
    <visual>
      <origin
        xyz="0 0 0"
        rpy="0 0 0" />
      <geometry>
        <mesh
          filename="package://alohamini2pro_urdf/alohamini2pro_meshes/Link2_dp.STL" />
      </geometry>
      <material
        name="">
        <color
          rgba="0.752941176470588 0.752941176470588 0.752941176470588 1" />
      </material>
    </visual>
    <collision>
      <origin
        xyz="0 0 0"
        rpy="0 0 0" />
      <geometry>
        <mesh
          filename="package://alohamini2pro_urdf/alohamini2pro_meshes/Link2_dp.STL" />
      </geometry>
    </collision>
  </link>
  <joint
    name="joint2_dp"
    type="fixed">
    <origin
      xyz="-0.1337 0.076522 0.063355"
      rpy="3.3411E-05 1.5707 2.618" />
    <parent
      link="base_link" />
    <child
      link="Link2_dp" />
    <axis
      xyz="-8.7287E-05 0 -1" />
  </joint>
  <link
    name="Link3_dp">
    <inertial>
      <origin
        xyz="-0.162560049646843 0.000838249024472069 -0.166596420117959"
        rpy="0 0 0" />
      <mass
        value="10.0950259540064" />
      <inertia
        ixx="0.137148263631157"
        ixy="0.00075554979583251"
        ixz="-0.0021920595125733"
        iyy="0.491701304000814"
        iyz="0.000197672739569835"
        izz="0.489542292988989" />
    </inertial>
    <visual>
      <origin
        xyz="0 0 0"
        rpy="0 0 0" />
      <geometry>
        <mesh
          filename="package://alohamini2pro_urdf/alohamini2pro_meshes/Link3_dp.STL" />
      </geometry>
      <material
        name="">
        <color
          rgba="0.752941176470588 0.752941176470588 0.752941176470588 1" />
      </material>
    </visual>
    <collision>
      <origin
        xyz="0 0 0"
        rpy="0 0 0" />
      <geometry>
        <mesh
          filename="package://alohamini2pro_urdf/alohamini2pro_meshes/Link3_dp.STL" />
      </geometry>
    </collision>
  </link>
  <joint
    name="joint3_dp"
    type="fixed">
    <origin
      xyz="-0.0014342 -0.15301 0.063355"
      rpy="1.5708 1.5708 0" />
    <parent
      link="base_link" />
    <child
      link="Link3_dp" />
    <axis
      xyz="0 0 -1" />
  </joint>
  <link
    name="Link4_dp">
    <inertial>
      <origin
        xyz="-0.01147039688487 -0.162560049646841 -0.145503153867049"
        rpy="0 0 0" />
      <mass
        value="10.0950259540064" />
      <inertia
        ixx="0.490253235356049"
        ixy="-0.00152060432658192"
        ixz="0.00103371556143014"
        iyy="0.137148263631157"
        iyz="0.00175035507329769"
        izz="0.490990361633755" />
    </inertial>
    <visual>
      <origin
        xyz="0 0 0"
        rpy="0 0 0" />
      <geometry>
        <mesh
          filename="package://alohamini2pro_urdf/alohamini2pro_meshes/Link4_dp.STL" />
      </geometry>
      <material
        name="">
        <color
          rgba="0.752941176470588 0.752941176470588 0.752941176470588 1" />
      </material>
    </visual>
    <collision>
      <origin
        xyz="0 0 0"
        rpy="0 0 0" />
      <geometry>
        <mesh
          filename="package://alohamini2pro_urdf/alohamini2pro_meshes/Link4_dp.STL" />
      </geometry>
    </collision>
  </link>
  <joint
    name="joint4_dp"
    type="fixed">
    <origin
      xyz="0.13115 0.076408 0.063355"
      rpy="-1.5708 0 -1.0472" />
    <parent
      link="base_link" />
    <child
      link="Link4_dp" />
    <axis
      xyz="0 0 -1" />
  </joint>
  <link
    name="back_camera">
    <inertial>
      <origin
        xyz="-0.640890595074529 -0.00093675959900047 0.610115206341962"
        rpy="0 0 0" />
      <mass
        value="10.0950259540064" />
      <inertia
        ixx="0.363696186887347"
        ixy="-0.000606965787943536"
        ixz="0.16886378863484"
        iyy="0.491701304000814"
        iyz="0.000491449425894143"
        izz="0.262994369732799" />
    </inertial>
    <visual>
      <origin
        xyz="0 0 0"
        rpy="0 0 0" />
      <geometry>
        <mesh
          filename="package://alohamini2pro_urdf/alohamini2pro_meshes/back_camera.STL" />
      </geometry>
      <material
        name="">
        <color
          rgba="0.752941176470588 0.752941176470588 0.752941176470588 1" />
      </material>
    </visual>
    <collision>
      <origin
        xyz="0 0 0"
        rpy="0 0 0" />
      <geometry>
        <mesh
          filename="package://alohamini2pro_urdf/alohamini2pro_meshes/back_camera.STL" />
      </geometry>
    </collision>
  </link>
  <joint
    name="back_camera_joint5_dp"
    type="fixed">
    <origin
      xyz="0.00034085 0.16827 1.0972"
      rpy="-3.1416 -0.63429 1.5708" />
    <parent
      link="base_link" />
    <child
      link="back_camera" />
    <axis
      xyz="0 0 0" />
  </joint>
  <link
    name="front_camera">
    <inertial>
      <origin
        xyz="0.667531496762255 -0.00090519797224118 0.570675109672329"
        rpy="0 0 0" />
      <mass
        value="10.0950259540064" />
      <inertia
        ixx="0.315541737557791"
        ixy="0.000394470234067806"
        ixz="-0.176196959887059"
        iyy="0.491701304000814"
        iyz="0.000674035043881233"
        izz="0.311148819062355" />
    </inertial>
    <visual>
      <origin
        xyz="0 0 0"
        rpy="0 0 0" />
      <geometry>
        <mesh
          filename="package://alohamini2pro_urdf/alohamini2pro_meshes/front_camera.STL" />
      </geometry>
      <material
        name="">
        <color
          rgba="0.752941176470588 0.752941176470588 0.752941176470588 1" />
      </material>
    </visual>
    <collision>
      <origin
        xyz="0 0 0"
        rpy="0 0 0" />
      <geometry>
        <mesh
          filename="package://alohamini2pro_urdf/alohamini2pro_meshes/front_camera.STL" />
      </geometry>
    </collision>
  </link>
  <joint
    name="front_camera_joint6_dp"
    type="fixed">
    <origin
      xyz="0.000309285647814801 -0.0549084504780031 1.10145847792887"
      rpy="-3.14159265358978 0.78538567812397 1.5707963267949" />
    <parent
      link="base_link" />
    <child
      link="front_camera" />
    <axis
      xyz="0 0 0" />
  </joint>

<!-- ========== LEFT ARM (Official ManiSkill SO100) ========== -->
  <!-- Position: positive X (like aloha_mini_virtual_base.urdf) -->
<link name="left_Base">
    <inertial>
      <origin xyz="-2.45960666746703E-07 0.0311418169687909 0.0175746661003382" rpy="0 0 0" />
      <mass value="0.193184127927598" />
      <inertia ixx="0.000137030709467877" ixy="2.10136126944992E-08" ixz="4.24087422551286E-09"
               iyy="0.000169089551209259" iyz="2.26514711036514E-05" izz="0.000145097720857224" />
    </inertial>
    <visual name="left_base_link_chassis">
      <origin xyz="0 0 0" rpy="0 0 0" />
      <geometry>
        <mesh filename="alohamini2pro_urdf/left_Base.STL" />
      </geometry>
      <material name="white" />
    </visual>
    <collision>
      <origin xyz="0 0 0" rpy="0 0 0" />
      <geometry>
        <mesh filename="alohamini2pro_urdf/left_Base.STL" />
      </geometry>
    </collision>
  </link>

  <joint name="left_base_joint" type="fixed">
    <origin xyz="0.18726 -0.0599 0.4775" rpy="0 0 0" />
    <parent link="vertical_link" />
    <child link="left_Base" />
  </joint>

 <link
    name="left_Rotation_Pitch">
    <inertial>
      <origin
        xyz="0.00386596201421711 -0.0138668105342394 0.0175130444101314"
        rpy="0 0 0" />
      <mass
        value="0.0317343546239167" />
      <inertia
        ixx="1.17593989685845E-05"
        ixy="5.33473261341667E-11"
        ixz="-1.16394634931486E-08"
        iyy="1.07148546551247E-05"
        iyz="-7.69540157839114E-10"
        izz="1.10186525393721E-05" />
    </inertial>
    <visual>
      <origin
        xyz="0 0 0"
        rpy="0 0 0" />
      <geometry>
        <mesh
          filename="package://alohamini2pro_urdf/alohamini2pro_meshes/left_Rotation_Pitch.STL" />
      </geometry>
      <material
        name="">
        <color
          rgba="0.752941176470588 0.752941176470588 0.752941176470588 1" />
      </material>
    </visual>
    <collision>
      <origin
        xyz="0 0 0"
        rpy="0 0 0" />
      <geometry>
        <mesh
          filename="package://alohamini2pro_urdf/alohamini2pro_meshes/left_Rotation_Pitch.STL" />
      </geometry>
    </collision>
  </link>
  <joint
    name="left_shoulder_pan"
    type="revolute">
    <origin
      xyz="0 0 0.062556"
      rpy="0 0 0" />
    <parent
      link="left_Base" />
    <child
      link="left_Rotation_Pitch" />
    <axis
      xyz="0 0 -1" />
    <limit
      lower="-3.14"
      upper="3.14"
      effort="0"
      velocity="0" />
  </joint>
  <link
    name="left_Upper_Arm">
    <inertial>
      <origin
        xyz="-0.00503066993187069 0.0711598496257564 0.0014399982311204"
        rpy="0 0 0" />
      <mass
        value="0.26488994104406" />
      <inertia
        ixx="0.000669893079441904"
        ixy="4.05289537389169E-06"
        ixz="-2.04604246519749E-07"
        iyy="0.000223738977833996"
        iyz="-1.24031242310942E-06"
        izz="0.000502976167412308" />
    </inertial>
    <visual>
      <origin
        xyz="0 0 0"
        rpy="0 0 0" />
      <geometry>
        <mesh
          filename="package://alohamini2pro_urdf/alohamini2pro_meshes/left_Upper_Arm.STL" />
      </geometry>
      <material
        name="">
        <color
          rgba="0.752941176470588 0.752941176470588 0.752941176470588 1" />
      </material>
    </visual>
    <collision>
      <origin
        xyz="0 0 0"
        rpy="0 0 0" />
      <geometry>
        <mesh
          filename="package://alohamini2pro_urdf/alohamini2pro_meshes/left_Upper_Arm.STL" />
      </geometry>
    </collision>
  </link>
  <joint
    name="left_shoulder_lift"
    type="revolute">
    <origin
      xyz="0 -0.029035 0.058223"
      rpy="0 1.5708 0" />
    <parent
      link="left_Rotation_Pitch" />
    <child
      link="left_Upper_Arm" />
    <axis
      xyz="0 0 -1" />
    <limit
      lower="-3.14"
      upper="3.14"
      effort="0"
      velocity="0" />
  </joint>
  <link
    name="left_Lower_Arm">
    <inertial>
      <origin
        xyz="0.00411591741430284 -0.0804551152818728 -0.00101438996817399"
        rpy="0 0 0" />
      <mass
        value="0.270278659255739" />
      <inertia
        ixx="0.000836242352707801"
        ixy="7.56437972650344E-06"
        ixz="1.34564062040202E-07"
        iyy="0.000207983856957914"
        iyz="-3.81626892414451E-06"
        izz="0.000676986981489906" />
    </inertial>
    <visual>
      <origin
        xyz="0 0 0"
        rpy="0 0 0" />
      <geometry>
        <mesh
          filename="package://alohamini2pro_urdf/alohamini2pro_meshes/left_Lower_Arm.STL" />
      </geometry>
      <material
        name="">
        <color
          rgba="0.752941176470588 0.752941176470588 0.752941176470588 1" />
      </material>
    </visual>
    <collision>
      <origin
        xyz="0 0 0"
        rpy="0 0 0" />
      <geometry>
        <mesh
          filename="package://alohamini2pro_urdf/alohamini2pro_meshes/left_Lower_Arm.STL" />
      </geometry>
    </collision>
  </link>
  <joint
    name="left_elbow_flex"
    type="revolute">
    <origin
      xyz="-0.041170749065642 0.128514358904429 0"
      rpy="0 0 0" />
    <parent
      link="left_Upper_Arm" />
    <child
      link="left_Lower_Arm" />
    <axis
      xyz="0 0 -1" />
    <limit
      lower="-3.14"
      upper="3.14"
      effort="0"
      velocity="0" />
  </joint>
  <link
    name="left_Wrist_Pitch_Roll">
    <inertial>
      <origin
        xyz="-0.000731389938048943 -0.0147937425780408 -0.000718021549161701"
        rpy="0 0 0" />
      <mass
        value="0.0304496388844339" />
      <inertia
        ixx="1.45088548152824E-05"
        ixy="-2.43324156971068E-07"
        ixz="1.64696078336802E-08"
        iyy="1.12953091793792E-05"
        iyz="5.07349732865443E-07"
        izz="8.22489621686965E-06" />
    </inertial>
    <visual>
      <origin
        xyz="0 0 0"
        rpy="0 0 0" />
      <geometry>
        <mesh
          filename="package://alohamini2pro_urdf/alohamini2pro_meshes/left_Wrist_Pitch_Roll.STL" />
      </geometry>
      <material
        name="">
        <color
          rgba="0.752941176470588 0.752941176470588 0.752941176470588 1" />
      </material>
    </visual>
    <collision>
      <origin
        xyz="0 0 0"
        rpy="0 0 0" />
      <geometry>
        <mesh
          filename="package://alohamini2pro_urdf/alohamini2pro_meshes/left_Wrist_Pitch_Roll.STL" />
      </geometry>
    </collision>
  </link>
  <joint
    name="left_wrist_flex"
    type="revolute">
    <origin
      xyz="0.00320470342874501 -0.198428485161884 0"
      rpy="0 0 0" />
    <parent
      link="left_Lower_Arm" />
    <child
      link="left_Wrist_Pitch_Roll" />
    <axis
      xyz="0 0 1" />
    <limit
      lower="-3.14"
      upper="3.14"
      effort="0"
      velocity="0" />
  </joint>
  <link
    name="left_wrist_yaw">
    <inertial>
      <origin
        xyz="-0.000117813013694405 0.0274410929028983 0.00965024408451137"
        rpy="0 0 0" />
      <mass
        value="0.105279930567343" />
      <inertia
        ixx="7.40447530125397E-05"
        ixy="4.80902969527966E-08"
        ixz="-4.93467864935505E-08"
        iyy="7.09874436497997E-05"
        iyz="1.85903139644103E-05"
        izz="4.53356638498229E-05" />
    </inertial>
    <visual>
      <origin
        xyz="0 0 0"
        rpy="0 0 0" />
      <geometry>
        <mesh
          filename="package://alohamini2pro_urdf/alohamini2pro_meshes/left_wrist_yaw.STL" />
      </geometry>
      <material
        name="">
        <color
          rgba="0.752941176470588 0.752941176470588 0.752941176470588 1" />
      </material>
    </visual>
    <collision>
      <origin
        xyz="0 0 0"
        rpy="0 0 0" />
      <geometry>
        <mesh
          filename="package://alohamini2pro_urdf/alohamini2pro_meshes/left_wrist_yaw.STL" />
      </geometry>
    </collision>
  </link>
  <joint
    name="left_wrist_yaw_joint"
    type="revolute">
    <origin
      xyz="-0.000915704840558335 -0.0281295188165527 -0.000966380385420608"
      rpy="3.14159257760848 1.5707963267949 0" />
    <parent
      link="left_Wrist_Pitch_Roll" />
    <child
      link="left_wrist_yaw" />
    <axis
      xyz="0 0 -1" />
    <limit
      lower="-3.14"
      upper="3.14"
      effort="0"
      velocity="0" />
  </joint>
  <link
    name="left_Fixed_Jaw">
    <inertial>
      <origin
        xyz="-0.009788697448233 -0.00779183152484197 0.024772169015474"
        rpy="0 0 0" />
      <mass
        value="0.0820209259289823" />
      <inertia
        ixx="5.46968854593741E-05"
        ixy="5.64423288927459E-07"
        ixz="9.06519097272961E-06"
        iyy="5.64802134373342E-05"
        iyz="-1.2174573644286E-06"
        izz="3.02312706629824E-05" />
    </inertial>
    <visual>
      <origin
        xyz="0 0 0"
        rpy="0 0 0" />
      <geometry>
        <mesh
          filename="package://alohamini2pro_urdf/alohamini2pro_meshes/left_Fixed_Jaw.STL" />
      </geometry>
      <material
        name="">
        <color
          rgba="0.752941176470588 0.752941176470588 0.752941176470588 1" />
      </material>
    </visual>
    <collision>
      <origin
        xyz="0 0 0"
        rpy="0 0 0" />
      <geometry>
        <mesh
          filename="package://alohamini2pro_urdf/alohamini2pro_meshes/left_Fixed_Jaw.STL" />
      </geometry>
    </collision>
  </link>
  <joint
    name="left_wrist_roll"
    type="revolute">
    <origin
      xyz="0 0.0609927440831215 -0.0242385261486938"
      rpy="-1.57079640339869 0 0" />
    <parent
      link="left_wrist_yaw" />
    <child
      link="left_Fixed_Jaw" />
    <axis
      xyz="0 0 1" />
    <limit
      lower="-3.14"
      upper="3.14"
      effort="0"
      velocity="0" />
  </joint>
  <link
    name="left_Moving_Jaw">
    <inertial>
      <origin
        xyz="-0.00191495762777895 -0.0312333699899828 0.00285164949308649"
        rpy="0 0 0" />
      <mass
        value="0.0288040630212379" />
      <inertia
        ixx="2.05481922687796E-05"
        ixy="-6.04064417680361E-07"
        ixz="-7.43538618229523E-10"
        iyy="5.96002371208446E-06"
        iyz="6.05082703416724E-09"
        izz="1.58458054447954E-05" />
    </inertial>
    <visual>
      <origin
        xyz="0 0 0"
        rpy="0 0 0" />
      <geometry>
        <mesh
          filename="package://alohamini2pro_urdf/alohamini2pro_meshes/left_Moving_Jaw.STL" />
      </geometry>
      <material
        name="">
        <color
          rgba="0.752941176470588 0.752941176470588 0.752941176470588 1" />
      </material>
    </visual>
    <collision>
      <origin
        xyz="0 0 0"
        rpy="0 0 0" />
      <geometry>
        <mesh
          filename="package://alohamini2pro_urdf/alohamini2pro_meshes/left_Moving_Jaw.STL" />
      </geometry>
    </collision>
  </link>
  <joint
    name="left_gripper"
    type="revolute">
    <origin
      xyz="0.02021444438295 0.0033063194616967 0.021614179864005"
      rpy="-1.5707963267949 0 3.14159265358979" />
    <parent
      link="left_Fixed_Jaw" />
    <child
      link="left_Moving_Jaw" />
    <axis
      xyz="0 0 1" />
    <limit
      lower="-3.14"
      upper="3.14"
      effort="0"
      velocity="0" />
  </joint>
  <link
    name="left_camera">
    <inertial>
      <origin
        xyz="-0.00363152315829868 0.157740718172186 -0.105680865715653"
        rpy="0 0 0" />
      <mass
        value="1.15055846064821" />
      <inertia
        ixx="0.0142106811421457"
        ixy="2.30316612860149E-05"
        ixz="-1.97427153101731E-05"
        iyy="0.00849398423463724"
        iyz="0.00342876254777693"
        izz="0.00733383401076117" />
    </inertial>
    <visual>
      <origin
        xyz="0 0 0"
        rpy="0 0 0" />
      <geometry>
        <mesh
          filename="package://alohamini2pro_urdf/alohamini2pro_meshes/left_camera.STL" />
      </geometry>
      <material
        name="">
        <color
          rgba="0.752941176470588 0.752941176470588 0.752941176470588 1" />
      </material>
    </visual>
    <collision>
      <origin
        xyz="0 0 0"
        rpy="0 0 0" />
      <geometry>
        <mesh
          filename="package://alohamini2pro_urdf/alohamini2pro_meshes/left_camera.STL" />
      </geometry>
    </collision>
  </link>
  <joint
    name="left_camera_joint8"
    type="fixed">
    <origin
      xyz="0.00251113132165192 -0.071341148343549 -0.00430701398654823"
      rpy="-0.436362675423314 0 0" />
    <parent
      link="left_Fixed_Jaw" />
    <child
      link="left_camera" />
    <axis
      xyz="0 0.906294954903738 0.422645779247862" />
  </joint>

<!-- ========== right ARM (Official ManiSkill SO100) ========== -->
  <!-- Position: positive X (like aloha_mini_virtual_base.urdf) -->
<link name="right_Base">
    <inertial>
      <origin xyz="-2.45960666746703E-07 0.0311418169687909 0.0175746661003382" rpy="0 0 0" />
      <mass value="0.193184127927598" />
      <inertia ixx="0.000137030709467877" ixy="2.10136126944992E-08" ixz="4.24087422551286E-09"
               iyy="0.000169089551209259" iyz="2.26514711036514E-05" izz="0.000145097720857224" />
    </inertial>
    <visual name="right_base_link_chassis">
      <origin xyz="0 0 0" rpy="0 0 0" />
      <geometry>
        <mesh filename="alohamini2pro_urdf/right_Base.STL" />
      </geometry>
      <material name="white" />
    </visual>
    <collision>
      <origin xyz="0 0 0" rpy="0 0 0" />
      <geometry>
        <mesh filename="alohamini2pro_urdf/right_Base.STL" />
      </geometry>
    </collision>
  </link>

  <joint name="right_base_joint" type="fixed">
    <origin xyz="-0.18726 -0.0599 0.4775" rpy="0 0 0" />
    <parent link="vertical_link" />
    <child link="right_Base" />
  </joint>

 <link
    name="right_Rotation_Pitch">
    <inertial>
      <origin
        xyz="0.00386596201421711 -0.0138668105342394 0.0175130444101314"
        rpy="0 0 0" />
      <mass
        value="0.0317343546239167" />
      <inertia
        ixx="1.17593989685845E-05"
        ixy="5.33473261341667E-11"
        ixz="-1.16394634931486E-08"
        iyy="1.07148546551247E-05"
        iyz="-7.69540157839114E-10"
        izz="1.10186525393721E-05" />
    </inertial>
    <visual>
      <origin
        xyz="0 0 0"
        rpy="0 0 0" />
      <geometry>
        <mesh
          filename="package://alohamini2pro_urdf/alohamini2pro_meshes/right_Rotation_Pitch.STL" />
      </geometry>
      <material
        name="">
        <color
          rgba="0.752941176470588 0.752941176470588 0.752941176470588 1" />
      </material>
    </visual>
    <collision>
      <origin
        xyz="0 0 0"
        rpy="0 0 0" />
      <geometry>
        <mesh
          filename="package://alohamini2pro_urdf/alohamini2pro_meshes/right_Rotation_Pitch.STL" />
      </geometry>
    </collision>
  </link>
  <joint
    name="right_shoulder_pan"
    type="revolute">
    <origin
      xyz="0 0 0.062556"
      rpy="0 0 0" />
    <parent
      link="right_Base" />
    <child
      link="right_Rotation_Pitch" />
    <axis
      xyz="0 0 -1" />
    <limit
      lower="-3.14"
      upper="3.14"
      effort="0"
      velocity="0" />
  </joint>
  <link
    name="right_Upper_Arm">
    <inertial>
      <origin
        xyz="-0.00503066993187069 0.0711598496257564 0.0014399982311204"
        rpy="0 0 0" />
      <mass
        value="0.26488994104406" />
      <inertia
        ixx="0.000669893079441904"
        ixy="4.05289537389169E-06"
        ixz="-2.04604246519749E-07"
        iyy="0.000223738977833996"
        iyz="-1.24031242310942E-06"
        izz="0.000502976167412308" />
    </inertial>
    <visual>
      <origin
        xyz="0 0 0"
        rpy="0 0 0" />
      <geometry>
        <mesh
          filename="package://alohamini2pro_urdf/alohamini2pro_meshes/right_Upper_Arm.STL" />
      </geometry>
      <material
        name="">
        <color
          rgba="0.752941176470588 0.752941176470588 0.752941176470588 1" />
      </material>
    </visual>
    <collision>
      <origin
        xyz="0 0 0"
        rpy="0 0 0" />
      <geometry>
        <mesh
          filename="package://alohamini2pro_urdf/alohamini2pro_meshes/right_Upper_Arm.STL" />
      </geometry>
    </collision>
  </link>
  <joint
    name="right_shoulder_lift"
    type="revolute">
    <origin
      xyz="0 -0.029035 0.058223"
      rpy="0 1.5708 0" />
    <parent
      link="right_Rotation_Pitch" />
    <child
      link="right_Upper_Arm" />
    <axis
      xyz="0 0 -1" />
    <limit
      lower="-3.14"
      upper="3.14"
      effort="0"
      velocity="0" />
  </joint>
  <link
    name="right_Lower_Arm">
    <inertial>
      <origin
        xyz="0.00411591741430284 -0.0804551152818728 -0.00101438996817399"
        rpy="0 0 0" />
      <mass
        value="0.270278659255739" />
      <inertia
        ixx="0.000836242352707801"
        ixy="7.56437972650344E-06"
        ixz="1.34564062040202E-07"
        iyy="0.000207983856957914"
        iyz="-3.81626892414451E-06"
        izz="0.000676986981489906" />
    </inertial>
    <visual>
      <origin
        xyz="0 0 0"
        rpy="0 0 0" />
      <geometry>
        <mesh
          filename="package://alohamini2pro_urdf/alohamini2pro_meshes/right_Lower_Arm.STL" />
      </geometry>
      <material
        name="">
        <color
          rgba="0.752941176470588 0.752941176470588 0.752941176470588 1" />
      </material>
    </visual>
    <collision>
      <origin
        xyz="0 0 0"
        rpy="0 0 0" />
      <geometry>
        <mesh
          filename="package://alohamini2pro_urdf/alohamini2pro_meshes/right_Lower_Arm.STL" />
      </geometry>
    </collision>
  </link>
  <joint
    name="right_elbow_flex"
    type="revolute">
    <origin
      xyz="-0.041170749065642 0.128514358904429 0"
      rpy="0 0 0" />
    <parent
      link="right_Upper_Arm" />
    <child
      link="right_Lower_Arm" />
    <axis
      xyz="0 0 -1" />
    <limit
      lower="-3.14"
      upper="3.14"
      effort="0"
      velocity="0" />
  </joint>
  <link
    name="right_Wrist_Pitch_Roll">
    <inertial>
      <origin
        xyz="-0.000731389938048943 -0.0147937425780408 -0.000718021549161701"
        rpy="0 0 0" />
      <mass
        value="0.0304496388844339" />
      <inertia
        ixx="1.45088548152824E-05"
        ixy="-2.43324156971068E-07"
        ixz="1.64696078336802E-08"
        iyy="1.12953091793792E-05"
        iyz="5.07349732865443E-07"
        izz="8.22489621686965E-06" />
    </inertial>
    <visual>
      <origin
        xyz="0 0 0"
        rpy="0 0 0" />
      <geometry>
        <mesh
          filename="package://alohamini2pro_urdf/alohamini2pro_meshes/right_Wrist_Pitch_Roll.STL" />
      </geometry>
      <material
        name="">
        <color
          rgba="0.752941176470588 0.752941176470588 0.752941176470588 1" />
      </material>
    </visual>
    <collision>
      <origin
        xyz="0 0 0"
        rpy="0 0 0" />
      <geometry>
        <mesh
          filename="package://alohamini2pro_urdf/alohamini2pro_meshes/right_Wrist_Pitch_Roll.STL" />
      </geometry>
    </collision>
  </link>
  <joint
    name="right_wrist_flex"
    type="revolute">
    <origin
      xyz="0.00320470342874501 -0.198428485161884 0"
      rpy="0 0 0" />
    <parent
      link="right_Lower_Arm" />
    <child
      link="right_Wrist_Pitch_Roll" />
    <axis
      xyz="0 0 1" />
    <limit
      lower="-3.14"
      upper="3.14"
      effort="0"
      velocity="0" />
  </joint>
  <link
    name="right_wrist_yaw">
    <inertial>
      <origin
        xyz="-0.000117813013694405 0.0274410929028983 0.00965024408451137"
        rpy="0 0 0" />
      <mass
        value="0.105279930567343" />
      <inertia
        ixx="7.40447530125397E-05"
        ixy="4.80902969527966E-08"
        ixz="-4.93467864935505E-08"
        iyy="7.09874436497997E-05"
        iyz="1.85903139644103E-05"
        izz="4.53356638498229E-05" />
    </inertial>
    <visual>
      <origin
        xyz="0 0 0"
        rpy="0 0 0" />
      <geometry>
        <mesh
          filename="package://alohamini2pro_urdf/alohamini2pro_meshes/right_wrist_yaw.STL" />
      </geometry>
      <material
        name="">
        <color
          rgba="0.752941176470588 0.752941176470588 0.752941176470588 1" />
      </material>
    </visual>
    <collision>
      <origin
        xyz="0 0 0"
        rpy="0 0 0" />
      <geometry>
        <mesh
          filename="package://alohamini2pro_urdf/alohamini2pro_meshes/right_wrist_yaw.STL" />
      </geometry>
    </collision>
  </link>
  <joint
    name="right_wrist_yaw_joint"
    type="revolute">
    <origin
      xyz="-0.000915704840558335 -0.0281295188165527 -0.000966380385420608"
      rpy="3.14159257760848 1.5707963267949 0" />
    <parent
      link="right_Wrist_Pitch_Roll" />
    <child
      link="right_wrist_yaw" />
    <axis
      xyz="0 0 -1" />
    <limit
      lower="-3.14"
      upper="3.14"
      effort="0"
      velocity="0" />
  </joint>
  <link
    name="right_Fixed_Jaw">
    <inertial>
      <origin
        xyz="-0.009788697448233 -0.00779183152484197 0.024772169015474"
        rpy="0 0 0" />
      <mass
        value="0.0820209259289823" />
      <inertia
        ixx="5.46968854593741E-05"
        ixy="5.64423288927459E-07"
        ixz="9.06519097272961E-06"
        iyy="5.64802134373342E-05"
        iyz="-1.2174573644286E-06"
        izz="3.02312706629824E-05" />
    </inertial>
    <visual>
      <origin
        xyz="0 0 0"
        rpy="0 0 0" />
      <geometry>
        <mesh
          filename="package://alohamini2pro_urdf/alohamini2pro_meshes/right_Fixed_Jaw.STL" />
      </geometry>
      <material
        name="">
        <color
          rgba="0.752941176470588 0.752941176470588 0.752941176470588 1" />
      </material>
    </visual>
    <collision>
      <origin
        xyz="0 0 0"
        rpy="0 0 0" />
      <geometry>
        <mesh
          filename="package://alohamini2pro_urdf/alohamini2pro_meshes/right_Fixed_Jaw.STL" />
      </geometry>
    </collision>
  </link>
  <joint
    name="right_wrist_roll"
    type="revolute">
    <origin
      xyz="0 0.0609927440831215 -0.0242385261486938"
      rpy="-1.57079640339869 0 0" />
    <parent
      link="right_wrist_yaw" />
    <child
      link="right_Fixed_Jaw" />
    <axis
      xyz="0 0 1" />
    <limit
      lower="-3.14"
      upper="3.14"
      effort="0"
      velocity="0" />
  </joint>
  <link
    name="right_Moving_Jaw">
    <inertial>
      <origin
        xyz="-0.00191495762777895 -0.0312333699899828 0.00285164949308649"
        rpy="0 0 0" />
      <mass
        value="0.0288040630212379" />
      <inertia
        ixx="2.05481922687796E-05"
        ixy="-6.04064417680361E-07"
        ixz="-7.43538618229523E-10"
        iyy="5.96002371208446E-06"
        iyz="6.05082703416724E-09"
        izz="1.58458054447954E-05" />
    </inertial>
    <visual>
      <origin
        xyz="0 0 0"
        rpy="0 0 0" />
      <geometry>
        <mesh
          filename="package://alohamini2pro_urdf/alohamini2pro_meshes/right_Moving_Jaw.STL" />
      </geometry>
      <material
        name="">
        <color
          rgba="0.752941176470588 0.752941176470588 0.752941176470588 1" />
      </material>
    </visual>
    <collision>
      <origin
        xyz="0 0 0"
        rpy="0 0 0" />
      <geometry>
        <mesh
          filename="package://alohamini2pro_urdf/alohamini2pro_meshes/right_Moving_Jaw.STL" />
      </geometry>
    </collision>
  </link>
  <joint
    name="right_gripper"
    type="revolute">
    <origin
      xyz="0.02021444438295 0.0033063194616967 0.021614179864005"
      rpy="-1.5707963267949 0 3.14159265358979" />
    <parent
      link="right_Fixed_Jaw" />
    <child
      link="right_Moving_Jaw" />
    <axis
      xyz="0 0 1" />
    <limit
      lower="-3.14"
      upper="3.14"
      effort="0"
      velocity="0" />
  </joint>
  <link
    name="right_camera">
    <inertial>
      <origin
        xyz="-0.00363152315829868 0.157740718172186 -0.105680865715653"
        rpy="0 0 0" />
      <mass
        value="1.15055846064821" />
      <inertia
        ixx="0.0142106811421457"
        ixy="2.30316612860149E-05"
        ixz="-1.97427153101731E-05"
        iyy="0.00849398423463724"
        iyz="0.00342876254777693"
        izz="0.00733383401076117" />
    </inertial>
    <visual>
      <origin
        xyz="0 0 0"
        rpy="0 0 0" />
      <geometry>
        <mesh
          filename="package://alohamini2pro_urdf/alohamini2pro_meshes/right_camera.STL" />
      </geometry>
      <material
        name="">
        <color
          rgba="0.752941176470588 0.752941176470588 0.752941176470588 1" />
      </material>
    </visual>
    <collision>
      <origin
        xyz="0 0 0"
        rpy="0 0 0" />
      <geometry>
        <mesh
          filename="package://alohamini2pro_urdf/alohamini2pro_meshes/right_camera.STL" />
      </geometry>
    </collision>
  </link>
  <joint
    name="right_camera_joint8"
    type="fixed">
    <origin
      xyz="0.00251113132165192 -0.071341148343549 -0.00430701398654823"
      rpy="-0.436362675423314 0 0" />
    <parent
      link="right_Fixed_Jaw" />
    <child
      link="right_camera" />
    <axis
      xyz="0 0.906294954903738 0.422645779247862" />
  </joint>

</robot>